EEEEEEEEEEEEEEEEEEEEE
======================================================================
ERROR: test_base_case_2 (__main__.SieveTest)
----------------------------------------------------------------------
Traceback (most recent call last):
  File "/home/furkan/csc209-w19/grading/mark_a3/marking_scripts/test_helpers.py", line 161, in _t
    stdout, stderr, returncode = self._run_exec(args=args, input_=input_, timeout=timeout, check=check)
  File "/home/furkan/csc209-w19/grading/mark_a3/marking_scripts/test_helpers.py", line 101, in _run_exec
    **kwargs)
  File "/home/furkan/csc209-w19/grading/mark_a3/marking_scripts/test_helpers.py", line 496, in _exec
    shell=shell)
  File "/usr/lib/python3.6/subprocess.py", line 709, in __init__
    restore_signals, start_new_session)
  File "/usr/lib/python3.6/subprocess.py", line 1344, in _execute_child
    raise child_exception_type(errno_num, err_msg, err_filename)
FileNotFoundError: [Errno 2] No such file or directory: './pfact': './pfact'

======================================================================
ERROR: test_base_case_3 (__main__.SieveTest)
----------------------------------------------------------------------
Traceback (most recent call last):
  File "/home/furkan/csc209-w19/grading/mark_a3/marking_scripts/test_helpers.py", line 161, in _t
    stdout, stderr, returncode = self._run_exec(args=args, input_=input_, timeout=timeout, check=check)
  File "/home/furkan/csc209-w19/grading/mark_a3/marking_scripts/test_helpers.py", line 101, in _run_exec
    **kwargs)
  File "/home/furkan/csc209-w19/grading/mark_a3/marking_scripts/test_helpers.py", line 496, in _exec
    shell=shell)
  File "/usr/lib/python3.6/subprocess.py", line 709, in __init__
    restore_signals, start_new_session)
  File "/usr/lib/python3.6/subprocess.py", line 1344, in _execute_child
    raise child_exception_type(errno_num, err_msg, err_filename)
FileNotFoundError: [Errno 2] No such file or directory: './pfact': './pfact'

======================================================================
ERROR: test_base_case_4 (__main__.SieveTest)
----------------------------------------------------------------------
Traceback (most recent call last):
  File "/home/furkan/csc209-w19/grading/mark_a3/marking_scripts/test_helpers.py", line 161, in _t
    stdout, stderr, returncode = self._run_exec(args=args, input_=input_, timeout=timeout, check=check)
  File "/home/furkan/csc209-w19/grading/mark_a3/marking_scripts/test_helpers.py", line 101, in _run_exec
    **kwargs)
  File "/home/furkan/csc209-w19/grading/mark_a3/marking_scripts/test_helpers.py", line 496, in _exec
    shell=shell)
  File "/usr/lib/python3.6/subprocess.py", line 709, in __init__
    restore_signals, start_new_session)
  File "/usr/lib/python3.6/subprocess.py", line 1344, in _execute_child
    raise child_exception_type(errno_num, err_msg, err_filename)
FileNotFoundError: [Errno 2] No such file or directory: './pfact': './pfact'

======================================================================
ERROR: test_cube (__main__.SieveTest)
----------------------------------------------------------------------
Traceback (most recent call last):
  File "/home/furkan/csc209-w19/grading/mark_a3/marking_scripts/test_helpers.py", line 161, in _t
    stdout, stderr, returncode = self._run_exec(args=args, input_=input_, timeout=timeout, check=check)
  File "/home/furkan/csc209-w19/grading/mark_a3/marking_scripts/test_helpers.py", line 101, in _run_exec
    **kwargs)
  File "/home/furkan/csc209-w19/grading/mark_a3/marking_scripts/test_helpers.py", line 496, in _exec
    shell=shell)
  File "/usr/lib/python3.6/subprocess.py", line 709, in __init__
    restore_signals, start_new_session)
  File "/usr/lib/python3.6/subprocess.py", line 1344, in _execute_child
    raise child_exception_type(errno_num, err_msg, err_filename)
FileNotFoundError: [Errno 2] No such file or directory: './pfact': './pfact'

======================================================================
ERROR: test_cube_and_another_large_prime (__main__.SieveTest)
----------------------------------------------------------------------
Traceback (most recent call last):
  File "/home/furkan/csc209-w19/grading/mark_a3/marking_scripts/test_helpers.py", line 161, in _t
    stdout, stderr, returncode = self._run_exec(args=args, input_=input_, timeout=timeout, check=check)
  File "/home/furkan/csc209-w19/grading/mark_a3/marking_scripts/test_helpers.py", line 101, in _run_exec
    **kwargs)
  File "/home/furkan/csc209-w19/grading/mark_a3/marking_scripts/test_helpers.py", line 496, in _exec
    shell=shell)
  File "/usr/lib/python3.6/subprocess.py", line 709, in __init__
    restore_signals, start_new_session)
  File "/usr/lib/python3.6/subprocess.py", line 1344, in _execute_child
    raise child_exception_type(errno_num, err_msg, err_filename)
FileNotFoundError: [Errno 2] No such file or directory: './pfact': './pfact'

======================================================================
ERROR: test_cube_and_another_prime_below_sqrt (__main__.SieveTest)
----------------------------------------------------------------------
Traceback (most recent call last):
  File "/home/furkan/csc209-w19/grading/mark_a3/marking_scripts/test_helpers.py", line 161, in _t
    stdout, stderr, returncode = self._run_exec(args=args, input_=input_, timeout=timeout, check=check)
  File "/home/furkan/csc209-w19/grading/mark_a3/marking_scripts/test_helpers.py", line 101, in _run_exec
    **kwargs)
  File "/home/furkan/csc209-w19/grading/mark_a3/marking_scripts/test_helpers.py", line 496, in _exec
    shell=shell)
  File "/usr/lib/python3.6/subprocess.py", line 709, in __init__
    restore_signals, start_new_session)
  File "/usr/lib/python3.6/subprocess.py", line 1344, in _execute_child
    raise child_exception_type(errno_num, err_msg, err_filename)
FileNotFoundError: [Errno 2] No such file or directory: './pfact': './pfact'

======================================================================
ERROR: test_cube_and_another_smaller_prime (__main__.SieveTest)
----------------------------------------------------------------------
Traceback (most recent call last):
  File "/home/furkan/csc209-w19/grading/mark_a3/marking_scripts/test_helpers.py", line 161, in _t
    stdout, stderr, returncode = self._run_exec(args=args, input_=input_, timeout=timeout, check=check)
  File "/home/furkan/csc209-w19/grading/mark_a3/marking_scripts/test_helpers.py", line 101, in _run_exec
    **kwargs)
  File "/home/furkan/csc209-w19/grading/mark_a3/marking_scripts/test_helpers.py", line 496, in _exec
    shell=shell)
  File "/usr/lib/python3.6/subprocess.py", line 709, in __init__
    restore_signals, start_new_session)
  File "/usr/lib/python3.6/subprocess.py", line 1344, in _execute_child
    raise child_exception_type(errno_num, err_msg, err_filename)
FileNotFoundError: [Errno 2] No such file or directory: './pfact': './pfact'

======================================================================
ERROR: test_exactly_2_primes (__main__.SieveTest)
----------------------------------------------------------------------
Traceback (most recent call last):
  File "/home/furkan/csc209-w19/grading/mark_a3/marking_scripts/test_helpers.py", line 161, in _t
    stdout, stderr, returncode = self._run_exec(args=args, input_=input_, timeout=timeout, check=check)
  File "/home/furkan/csc209-w19/grading/mark_a3/marking_scripts/test_helpers.py", line 101, in _run_exec
    **kwargs)
  File "/home/furkan/csc209-w19/grading/mark_a3/marking_scripts/test_helpers.py", line 496, in _exec
    shell=shell)
  File "/usr/lib/python3.6/subprocess.py", line 709, in __init__
    restore_signals, start_new_session)
  File "/usr/lib/python3.6/subprocess.py", line 1344, in _execute_child
    raise child_exception_type(errno_num, err_msg, err_filename)
FileNotFoundError: [Errno 2] No such file or directory: './pfact': './pfact'

======================================================================
ERROR: test_exactly_2_primes_diff (__main__.SieveTest)
----------------------------------------------------------------------
Traceback (most recent call last):
  File "/home/furkan/csc209-w19/grading/mark_a3/marking_scripts/test_helpers.py", line 161, in _t
    stdout, stderr, returncode = self._run_exec(args=args, input_=input_, timeout=timeout, check=check)
  File "/home/furkan/csc209-w19/grading/mark_a3/marking_scripts/test_helpers.py", line 101, in _run_exec
    **kwargs)
  File "/home/furkan/csc209-w19/grading/mark_a3/marking_scripts/test_helpers.py", line 496, in _exec
    shell=shell)
  File "/usr/lib/python3.6/subprocess.py", line 709, in __init__
    restore_signals, start_new_session)
  File "/usr/lib/python3.6/subprocess.py", line 1344, in _execute_child
    raise child_exception_type(errno_num, err_msg, err_filename)
FileNotFoundError: [Errno 2] No such file or directory: './pfact': './pfact'

======================================================================
ERROR: test_four_prime_factors (__main__.SieveTest)
----------------------------------------------------------------------
Traceback (most recent call last):
  File "/home/furkan/csc209-w19/grading/mark_a3/marking_scripts/test_helpers.py", line 161, in _t
    stdout, stderr, returncode = self._run_exec(args=args, input_=input_, timeout=timeout, check=check)
  File "/home/furkan/csc209-w19/grading/mark_a3/marking_scripts/test_helpers.py", line 101, in _run_exec
    **kwargs)
  File "/home/furkan/csc209-w19/grading/mark_a3/marking_scripts/test_helpers.py", line 496, in _exec
    shell=shell)
  File "/usr/lib/python3.6/subprocess.py", line 709, in __init__
    restore_signals, start_new_session)
  File "/usr/lib/python3.6/subprocess.py", line 1344, in _execute_child
    raise child_exception_type(errno_num, err_msg, err_filename)
FileNotFoundError: [Errno 2] No such file or directory: './pfact': './pfact'

======================================================================
ERROR: test_large_prime (__main__.SieveTest)
----------------------------------------------------------------------
Traceback (most recent call last):
  File "/home/furkan/csc209-w19/grading/mark_a3/marking_scripts/test_helpers.py", line 161, in _t
    stdout, stderr, returncode = self._run_exec(args=args, input_=input_, timeout=timeout, check=check)
  File "/home/furkan/csc209-w19/grading/mark_a3/marking_scripts/test_helpers.py", line 101, in _run_exec
    **kwargs)
  File "/home/furkan/csc209-w19/grading/mark_a3/marking_scripts/test_helpers.py", line 496, in _exec
    shell=shell)
  File "/usr/lib/python3.6/subprocess.py", line 709, in __init__
    restore_signals, start_new_session)
  File "/usr/lib/python3.6/subprocess.py", line 1344, in _execute_child
    raise child_exception_type(errno_num, err_msg, err_filename)
FileNotFoundError: [Errno 2] No such file or directory: './pfact': './pfact'

======================================================================
ERROR: test_many_filters (__main__.SieveTest)
----------------------------------------------------------------------
Traceback (most recent call last):
  File "/home/furkan/csc209-w19/grading/mark_a3/marking_scripts/test_helpers.py", line 161, in _t
    stdout, stderr, returncode = self._run_exec(args=args, input_=input_, timeout=timeout, check=check)
  File "/home/furkan/csc209-w19/grading/mark_a3/marking_scripts/test_helpers.py", line 101, in _run_exec
    **kwargs)
  File "/home/furkan/csc209-w19/grading/mark_a3/marking_scripts/test_helpers.py", line 496, in _exec
    shell=shell)
  File "/usr/lib/python3.6/subprocess.py", line 709, in __init__
    restore_signals, start_new_session)
  File "/usr/lib/python3.6/subprocess.py", line 1344, in _execute_child
    raise child_exception_type(errno_num, err_msg, err_filename)
FileNotFoundError: [Errno 2] No such file or directory: './pfact': './pfact'

======================================================================
ERROR: test_many_many_filters (__main__.SieveTest)
----------------------------------------------------------------------
Traceback (most recent call last):
  File "/home/furkan/csc209-w19/grading/mark_a3/marking_scripts/test_helpers.py", line 161, in _t
    stdout, stderr, returncode = self._run_exec(args=args, input_=input_, timeout=timeout, check=check)
  File "/home/furkan/csc209-w19/grading/mark_a3/marking_scripts/test_helpers.py", line 101, in _run_exec
    **kwargs)
  File "/home/furkan/csc209-w19/grading/mark_a3/marking_scripts/test_helpers.py", line 496, in _exec
    shell=shell)
  File "/usr/lib/python3.6/subprocess.py", line 709, in __init__
    restore_signals, start_new_session)
  File "/usr/lib/python3.6/subprocess.py", line 1344, in _execute_child
    raise child_exception_type(errno_num, err_msg, err_filename)
FileNotFoundError: [Errno 2] No such file or directory: './pfact': './pfact'

======================================================================
ERROR: test_perfect_square_of_primes (__main__.SieveTest)
----------------------------------------------------------------------
Traceback (most recent call last):
  File "/home/furkan/csc209-w19/grading/mark_a3/marking_scripts/test_helpers.py", line 161, in _t
    stdout, stderr, returncode = self._run_exec(args=args, input_=input_, timeout=timeout, check=check)
  File "/home/furkan/csc209-w19/grading/mark_a3/marking_scripts/test_helpers.py", line 101, in _run_exec
    **kwargs)
  File "/home/furkan/csc209-w19/grading/mark_a3/marking_scripts/test_helpers.py", line 496, in _exec
    shell=shell)
  File "/usr/lib/python3.6/subprocess.py", line 709, in __init__
    restore_signals, start_new_session)
  File "/usr/lib/python3.6/subprocess.py", line 1344, in _execute_child
    raise child_exception_type(errno_num, err_msg, err_filename)
FileNotFoundError: [Errno 2] No such file or directory: './pfact': './pfact'

======================================================================
ERROR: test_prime (__main__.SieveTest)
----------------------------------------------------------------------
Traceback (most recent call last):
  File "/home/furkan/csc209-w19/grading/mark_a3/marking_scripts/test_helpers.py", line 161, in _t
    stdout, stderr, returncode = self._run_exec(args=args, input_=input_, timeout=timeout, check=check)
  File "/home/furkan/csc209-w19/grading/mark_a3/marking_scripts/test_helpers.py", line 101, in _run_exec
    **kwargs)
  File "/home/furkan/csc209-w19/grading/mark_a3/marking_scripts/test_helpers.py", line 496, in _exec
    shell=shell)
  File "/usr/lib/python3.6/subprocess.py", line 709, in __init__
    restore_signals, start_new_session)
  File "/usr/lib/python3.6/subprocess.py", line 1344, in _execute_child
    raise child_exception_type(errno_num, err_msg, err_filename)
FileNotFoundError: [Errno 2] No such file or directory: './pfact': './pfact'

======================================================================
ERROR: test_prime_diff (__main__.SieveTest)
----------------------------------------------------------------------
Traceback (most recent call last):
  File "/home/furkan/csc209-w19/grading/mark_a3/marking_scripts/test_helpers.py", line 161, in _t
    stdout, stderr, returncode = self._run_exec(args=args, input_=input_, timeout=timeout, check=check)
  File "/home/furkan/csc209-w19/grading/mark_a3/marking_scripts/test_helpers.py", line 101, in _run_exec
    **kwargs)
  File "/home/furkan/csc209-w19/grading/mark_a3/marking_scripts/test_helpers.py", line 496, in _exec
    shell=shell)
  File "/usr/lib/python3.6/subprocess.py", line 709, in __init__
    restore_signals, start_new_session)
  File "/usr/lib/python3.6/subprocess.py", line 1344, in _execute_child
    raise child_exception_type(errno_num, err_msg, err_filename)
FileNotFoundError: [Errno 2] No such file or directory: './pfact': './pfact'

======================================================================
ERROR: test_square_and_larger_1025 (__main__.SieveTest)
----------------------------------------------------------------------
Traceback (most recent call last):
  File "/home/furkan/csc209-w19/grading/mark_a3/marking_scripts/test_helpers.py", line 161, in _t
    stdout, stderr, returncode = self._run_exec(args=args, input_=input_, timeout=timeout, check=check)
  File "/home/furkan/csc209-w19/grading/mark_a3/marking_scripts/test_helpers.py", line 101, in _run_exec
    **kwargs)
  File "/home/furkan/csc209-w19/grading/mark_a3/marking_scripts/test_helpers.py", line 496, in _exec
    shell=shell)
  File "/usr/lib/python3.6/subprocess.py", line 709, in __init__
    restore_signals, start_new_session)
  File "/usr/lib/python3.6/subprocess.py", line 1344, in _execute_child
    raise child_exception_type(errno_num, err_msg, err_filename)
FileNotFoundError: [Errno 2] No such file or directory: './pfact': './pfact'

======================================================================
ERROR: test_square_and_smaller_1183 (__main__.SieveTest)
----------------------------------------------------------------------
Traceback (most recent call last):
  File "/home/furkan/csc209-w19/grading/mark_a3/marking_scripts/test_helpers.py", line 161, in _t
    stdout, stderr, returncode = self._run_exec(args=args, input_=input_, timeout=timeout, check=check)
  File "/home/furkan/csc209-w19/grading/mark_a3/marking_scripts/test_helpers.py", line 101, in _run_exec
    **kwargs)
  File "/home/furkan/csc209-w19/grading/mark_a3/marking_scripts/test_helpers.py", line 496, in _exec
    shell=shell)
  File "/usr/lib/python3.6/subprocess.py", line 709, in __init__
    restore_signals, start_new_session)
  File "/usr/lib/python3.6/subprocess.py", line 1344, in _execute_child
    raise child_exception_type(errno_num, err_msg, err_filename)
FileNotFoundError: [Errno 2] No such file or directory: './pfact': './pfact'

======================================================================
ERROR: test_square_product_of_primes (__main__.SieveTest)
----------------------------------------------------------------------
Traceback (most recent call last):
  File "/home/furkan/csc209-w19/grading/mark_a3/marking_scripts/test_helpers.py", line 161, in _t
    stdout, stderr, returncode = self._run_exec(args=args, input_=input_, timeout=timeout, check=check)
  File "/home/furkan/csc209-w19/grading/mark_a3/marking_scripts/test_helpers.py", line 101, in _run_exec
    **kwargs)
  File "/home/furkan/csc209-w19/grading/mark_a3/marking_scripts/test_helpers.py", line 496, in _exec
    shell=shell)
  File "/usr/lib/python3.6/subprocess.py", line 709, in __init__
    restore_signals, start_new_session)
  File "/usr/lib/python3.6/subprocess.py", line 1344, in _execute_child
    raise child_exception_type(errno_num, err_msg, err_filename)
FileNotFoundError: [Errno 2] No such file or directory: './pfact': './pfact'

======================================================================
ERROR: test_three_prime_factors (__main__.SieveTest)
----------------------------------------------------------------------
Traceback (most recent call last):
  File "/home/furkan/csc209-w19/grading/mark_a3/marking_scripts/test_helpers.py", line 161, in _t
    stdout, stderr, returncode = self._run_exec(args=args, input_=input_, timeout=timeout, check=check)
  File "/home/furkan/csc209-w19/grading/mark_a3/marking_scripts/test_helpers.py", line 101, in _run_exec
    **kwargs)
  File "/home/furkan/csc209-w19/grading/mark_a3/marking_scripts/test_helpers.py", line 496, in _exec
    shell=shell)
  File "/usr/lib/python3.6/subprocess.py", line 709, in __init__
    restore_signals, start_new_session)
  File "/usr/lib/python3.6/subprocess.py", line 1344, in _execute_child
    raise child_exception_type(errno_num, err_msg, err_filename)
FileNotFoundError: [Errno 2] No such file or directory: './pfact': './pfact'

======================================================================
ERROR: test_too_many_filters (__main__.SieveTest)
----------------------------------------------------------------------
Traceback (most recent call last):
  File "/home/furkan/csc209-w19/grading/mark_a3/marking_scripts/test_helpers.py", line 161, in _t
    stdout, stderr, returncode = self._run_exec(args=args, input_=input_, timeout=timeout, check=check)
  File "/home/furkan/csc209-w19/grading/mark_a3/marking_scripts/test_helpers.py", line 101, in _run_exec
    **kwargs)
  File "/home/furkan/csc209-w19/grading/mark_a3/marking_scripts/test_helpers.py", line 496, in _exec
    shell=shell)
  File "/usr/lib/python3.6/subprocess.py", line 709, in __init__
    restore_signals, start_new_session)
  File "/usr/lib/python3.6/subprocess.py", line 1344, in _execute_child
    raise child_exception_type(errno_num, err_msg, err_filename)
FileNotFoundError: [Errno 2] No such file or directory: './pfact': './pfact'

----------------------------------------------------------------------
Ran 21 tests in 0.048s

FAILED (errors=21)
