EEEEEEEEE
======================================================================
ERROR: test_argument_of_zero (__main__.ArgumentsTest)
----------------------------------------------------------------------
Traceback (most recent call last):
  File "/home/furkan/csc209-w19/grading/mark_a3/marking_scripts/test_helpers.py", line 161, in _t
    stdout, stderr, returncode = self._run_exec(args=args, input_=input_, timeout=timeout, check=check)
  File "/home/furkan/csc209-w19/grading/mark_a3/marking_scripts/test_helpers.py", line 101, in _run_exec
    **kwargs)
  File "/home/furkan/csc209-w19/grading/mark_a3/marking_scripts/test_helpers.py", line 496, in _exec
    shell=shell)
  File "/usr/lib/python3.6/subprocess.py", line 709, in __init__
    restore_signals, start_new_session)
  File "/usr/lib/python3.6/subprocess.py", line 1344, in _execute_child
    raise child_exception_type(errno_num, err_msg, err_filename)
FileNotFoundError: [Errno 2] No such file or directory: './pfact': './pfact'

======================================================================
ERROR: test_missing_arg (__main__.ArgumentsTest)
----------------------------------------------------------------------
Traceback (most recent call last):
  File "/home/furkan/csc209-w19/grading/mark_a3/marking_scripts/test_helpers.py", line 161, in _t
    stdout, stderr, returncode = self._run_exec(args=args, input_=input_, timeout=timeout, check=check)
  File "/home/furkan/csc209-w19/grading/mark_a3/marking_scripts/test_helpers.py", line 101, in _run_exec
    **kwargs)
  File "/home/furkan/csc209-w19/grading/mark_a3/marking_scripts/test_helpers.py", line 496, in _exec
    shell=shell)
  File "/usr/lib/python3.6/subprocess.py", line 709, in __init__
    restore_signals, start_new_session)
  File "/usr/lib/python3.6/subprocess.py", line 1344, in _execute_child
    raise child_exception_type(errno_num, err_msg, err_filename)
FileNotFoundError: [Errno 2] No such file or directory: './pfact': './pfact'

======================================================================
ERROR: test_mixed_arg_78a (__main__.ArgumentsTest)
----------------------------------------------------------------------
Traceback (most recent call last):
  File "/home/furkan/csc209-w19/grading/mark_a3/marking_scripts/test_helpers.py", line 161, in _t
    stdout, stderr, returncode = self._run_exec(args=args, input_=input_, timeout=timeout, check=check)
  File "/home/furkan/csc209-w19/grading/mark_a3/marking_scripts/test_helpers.py", line 101, in _run_exec
    **kwargs)
  File "/home/furkan/csc209-w19/grading/mark_a3/marking_scripts/test_helpers.py", line 496, in _exec
    shell=shell)
  File "/usr/lib/python3.6/subprocess.py", line 709, in __init__
    restore_signals, start_new_session)
  File "/usr/lib/python3.6/subprocess.py", line 1344, in _execute_child
    raise child_exception_type(errno_num, err_msg, err_filename)
FileNotFoundError: [Errno 2] No such file or directory: './pfact': './pfact'

======================================================================
ERROR: test_negative_argument (__main__.ArgumentsTest)
----------------------------------------------------------------------
Traceback (most recent call last):
  File "/home/furkan/csc209-w19/grading/mark_a3/marking_scripts/test_helpers.py", line 161, in _t
    stdout, stderr, returncode = self._run_exec(args=args, input_=input_, timeout=timeout, check=check)
  File "/home/furkan/csc209-w19/grading/mark_a3/marking_scripts/test_helpers.py", line 101, in _run_exec
    **kwargs)
  File "/home/furkan/csc209-w19/grading/mark_a3/marking_scripts/test_helpers.py", line 496, in _exec
    shell=shell)
  File "/usr/lib/python3.6/subprocess.py", line 709, in __init__
    restore_signals, start_new_session)
  File "/usr/lib/python3.6/subprocess.py", line 1344, in _execute_child
    raise child_exception_type(errno_num, err_msg, err_filename)
FileNotFoundError: [Errno 2] No such file or directory: './pfact': './pfact'

======================================================================
ERROR: test_non_integer_arg (__main__.ArgumentsTest)
----------------------------------------------------------------------
Traceback (most recent call last):
  File "/home/furkan/csc209-w19/grading/mark_a3/marking_scripts/test_helpers.py", line 161, in _t
    stdout, stderr, returncode = self._run_exec(args=args, input_=input_, timeout=timeout, check=check)
  File "/home/furkan/csc209-w19/grading/mark_a3/marking_scripts/test_helpers.py", line 101, in _run_exec
    **kwargs)
  File "/home/furkan/csc209-w19/grading/mark_a3/marking_scripts/test_helpers.py", line 496, in _exec
    shell=shell)
  File "/usr/lib/python3.6/subprocess.py", line 709, in __init__
    restore_signals, start_new_session)
  File "/usr/lib/python3.6/subprocess.py", line 1344, in _execute_child
    raise child_exception_type(errno_num, err_msg, err_filename)
FileNotFoundError: [Errno 2] No such file or directory: './pfact': './pfact'

======================================================================
ERROR: test_non_numeric_arg (__main__.ArgumentsTest)
----------------------------------------------------------------------
Traceback (most recent call last):
  File "/home/furkan/csc209-w19/grading/mark_a3/marking_scripts/test_helpers.py", line 161, in _t
    stdout, stderr, returncode = self._run_exec(args=args, input_=input_, timeout=timeout, check=check)
  File "/home/furkan/csc209-w19/grading/mark_a3/marking_scripts/test_helpers.py", line 101, in _run_exec
    **kwargs)
  File "/home/furkan/csc209-w19/grading/mark_a3/marking_scripts/test_helpers.py", line 496, in _exec
    shell=shell)
  File "/usr/lib/python3.6/subprocess.py", line 709, in __init__
    restore_signals, start_new_session)
  File "/usr/lib/python3.6/subprocess.py", line 1344, in _execute_child
    raise child_exception_type(errno_num, err_msg, err_filename)
FileNotFoundError: [Errno 2] No such file or directory: './pfact': './pfact'

======================================================================
ERROR: test_space_in_arg (__main__.ArgumentsTest)
----------------------------------------------------------------------
Traceback (most recent call last):
  File "/home/furkan/csc209-w19/grading/mark_a3/marking_scripts/test_helpers.py", line 161, in _t
    stdout, stderr, returncode = self._run_exec(args=args, input_=input_, timeout=timeout, check=check)
  File "/home/furkan/csc209-w19/grading/mark_a3/marking_scripts/test_helpers.py", line 101, in _run_exec
    **kwargs)
  File "/home/furkan/csc209-w19/grading/mark_a3/marking_scripts/test_helpers.py", line 496, in _exec
    shell=shell)
  File "/usr/lib/python3.6/subprocess.py", line 709, in __init__
    restore_signals, start_new_session)
  File "/usr/lib/python3.6/subprocess.py", line 1344, in _execute_child
    raise child_exception_type(errno_num, err_msg, err_filename)
FileNotFoundError: [Errno 2] No such file or directory: './pfact': './pfact'

======================================================================
ERROR: test_too_many_args (__main__.ArgumentsTest)
----------------------------------------------------------------------
Traceback (most recent call last):
  File "/home/furkan/csc209-w19/grading/mark_a3/marking_scripts/test_helpers.py", line 161, in _t
    stdout, stderr, returncode = self._run_exec(args=args, input_=input_, timeout=timeout, check=check)
  File "/home/furkan/csc209-w19/grading/mark_a3/marking_scripts/test_helpers.py", line 101, in _run_exec
    **kwargs)
  File "/home/furkan/csc209-w19/grading/mark_a3/marking_scripts/test_helpers.py", line 496, in _exec
    shell=shell)
  File "/usr/lib/python3.6/subprocess.py", line 709, in __init__
    restore_signals, start_new_session)
  File "/usr/lib/python3.6/subprocess.py", line 1344, in _execute_child
    raise child_exception_type(errno_num, err_msg, err_filename)
FileNotFoundError: [Errno 2] No such file or directory: './pfact': './pfact'

======================================================================
ERROR: test_valid_arg (__main__.ArgumentsTest)
----------------------------------------------------------------------
Traceback (most recent call last):
  File "/home/furkan/csc209-w19/grading/mark_a3/marking_scripts/test_helpers.py", line 161, in _t
    stdout, stderr, returncode = self._run_exec(args=args, input_=input_, timeout=timeout, check=check)
  File "/home/furkan/csc209-w19/grading/mark_a3/marking_scripts/test_helpers.py", line 101, in _run_exec
    **kwargs)
  File "/home/furkan/csc209-w19/grading/mark_a3/marking_scripts/test_helpers.py", line 496, in _exec
    shell=shell)
  File "/usr/lib/python3.6/subprocess.py", line 709, in __init__
    restore_signals, start_new_session)
  File "/usr/lib/python3.6/subprocess.py", line 1344, in _execute_child
    raise child_exception_type(errno_num, err_msg, err_filename)
FileNotFoundError: [Errno 2] No such file or directory: './pfact': './pfact'

----------------------------------------------------------------------
Ran 9 tests in 0.035s

FAILED (errors=9)
