EEE
======================================================================
ERROR: test_empty (__main__.SieveTest)
----------------------------------------------------------------------
Traceback (most recent call last):
  File "/home/furkan/csc209-w19/grading/mark_a3/marking_scripts/test_helpers.py", line 161, in _t
    stdout, stderr, returncode = self._run_exec(args=args, input_=input_, timeout=timeout, check=check)
  File "/home/furkan/csc209-w19/grading/mark_a3/marking_scripts/test_helpers.py", line 101, in _run_exec
    **kwargs)
  File "/home/furkan/csc209-w19/grading/mark_a3/marking_scripts/test_helpers.py", line 496, in _exec
    shell=shell)
  File "/usr/lib/python3.6/subprocess.py", line 709, in __init__
    restore_signals, start_new_session)
  File "/usr/lib/python3.6/subprocess.py", line 1344, in _execute_child
    raise child_exception_type(errno_num, err_msg, err_filename)
FileNotFoundError: [Errno 2] No such file or directory: './filter_tester': './filter_tester'

======================================================================
ERROR: test_multi_value (__main__.SieveTest)
----------------------------------------------------------------------
Traceback (most recent call last):
  File "/home/furkan/csc209-w19/grading/mark_a3/marking_scripts/test_helpers.py", line 161, in _t
    stdout, stderr, returncode = self._run_exec(args=args, input_=input_, timeout=timeout, check=check)
  File "/home/furkan/csc209-w19/grading/mark_a3/marking_scripts/test_helpers.py", line 101, in _run_exec
    **kwargs)
  File "/home/furkan/csc209-w19/grading/mark_a3/marking_scripts/test_helpers.py", line 496, in _exec
    shell=shell)
  File "/usr/lib/python3.6/subprocess.py", line 709, in __init__
    restore_signals, start_new_session)
  File "/usr/lib/python3.6/subprocess.py", line 1344, in _execute_child
    raise child_exception_type(errno_num, err_msg, err_filename)
FileNotFoundError: [Errno 2] No such file or directory: './filter_tester': './filter_tester'

======================================================================
ERROR: test_single_value (__main__.SieveTest)
----------------------------------------------------------------------
Traceback (most recent call last):
  File "/home/furkan/csc209-w19/grading/mark_a3/marking_scripts/test_helpers.py", line 161, in _t
    stdout, stderr, returncode = self._run_exec(args=args, input_=input_, timeout=timeout, check=check)
  File "/home/furkan/csc209-w19/grading/mark_a3/marking_scripts/test_helpers.py", line 101, in _run_exec
    **kwargs)
  File "/home/furkan/csc209-w19/grading/mark_a3/marking_scripts/test_helpers.py", line 496, in _exec
    shell=shell)
  File "/usr/lib/python3.6/subprocess.py", line 709, in __init__
    restore_signals, start_new_session)
  File "/usr/lib/python3.6/subprocess.py", line 1344, in _execute_child
    raise child_exception_type(errno_num, err_msg, err_filename)
FileNotFoundError: [Errno 2] No such file or directory: './filter_tester': './filter_tester'

----------------------------------------------------------------------
Ran 3 tests in 0.023s

FAILED (errors=3)
